2023-01-02 11:06:55,001 INFO    StreamThr :9560 [internal.py:wandb_internal():87] W&B internal server running at pid: 9560, started at: 2023-01-02 11:06:54.993744
2023-01-02 11:06:55,009 DEBUG   HandlerThread:9560 [handler.py:handle_request():139] handle_request: status
2023-01-02 11:06:55,017 DEBUG   SenderThread:9560 [sender.py:send_request():317] send_request: status
2023-01-02 11:06:55,073 DEBUG   SenderThread:9560 [sender.py:send():303] send: header
2023-01-02 11:06:55,073 INFO    WriterThread:9560 [datastore.py:open_for_write():75] open: C:\Users\simplon\Desktop\Notebooks\Dossier_Projet_Fil_Rouge\Notebook\wandb\run-20230102_110654-24m9el1p\run-24m9el1p.wandb
2023-01-02 11:06:55,466 DEBUG   SenderThread:9560 [sender.py:send():303] send: run
2023-01-02 11:06:58,753 ERROR   SenderThread:9560 [retry.py:__call__():154] Retry attempt failed:
Traceback (most recent call last):
  File "C:\Users\simplon\anaconda3\lib\site-packages\urllib3\connection.py", line 174, in _new_conn
    conn = connection.create_connection(
  File "C:\Users\simplon\anaconda3\lib\site-packages\urllib3\util\connection.py", line 72, in create_connection
    for res in socket.getaddrinfo(host, port, family, socket.SOCK_STREAM):
  File "C:\Users\simplon\anaconda3\lib\socket.py", line 918, in getaddrinfo
    for res in _socket.getaddrinfo(host, port, family, type, proto, flags):
socket.gaierror: [Errno 11001] getaddrinfo failed

During handling of the above exception, another exception occurred:

Traceback (most recent call last):
  File "C:\Users\simplon\anaconda3\lib\site-packages\urllib3\connectionpool.py", line 703, in urlopen
    httplib_response = self._make_request(
  File "C:\Users\simplon\anaconda3\lib\site-packages\urllib3\connectionpool.py", line 386, in _make_request
    self._validate_conn(conn)
  File "C:\Users\simplon\anaconda3\lib\site-packages\urllib3\connectionpool.py", line 1042, in _validate_conn
    conn.connect()
  File "C:\Users\simplon\anaconda3\lib\site-packages\urllib3\connection.py", line 358, in connect
    self.sock = conn = self._new_conn()
  File "C:\Users\simplon\anaconda3\lib\site-packages\urllib3\connection.py", line 186, in _new_conn
    raise NewConnectionError(
urllib3.exceptions.NewConnectionError: <urllib3.connection.HTTPSConnection object at 0x0000020E88446820>: Failed to establish a new connection: [Errno 11001] getaddrinfo failed

During handling of the above exception, another exception occurred:

Traceback (most recent call last):
  File "C:\Users\simplon\anaconda3\lib\site-packages\requests\adapters.py", line 489, in send
    resp = conn.urlopen(
  File "C:\Users\simplon\anaconda3\lib\site-packages\urllib3\connectionpool.py", line 787, in urlopen
    retries = retries.increment(
  File "C:\Users\simplon\anaconda3\lib\site-packages\urllib3\util\retry.py", line 592, in increment
    raise MaxRetryError(_pool, url, error or ResponseError(cause))
urllib3.exceptions.MaxRetryError: HTTPSConnectionPool(host='api.wandb.ai', port=443): Max retries exceeded with url: /graphql (Caused by NewConnectionError('<urllib3.connection.HTTPSConnection object at 0x0000020E88446820>: Failed to establish a new connection: [Errno 11001] getaddrinfo failed'))

During handling of the above exception, another exception occurred:

Traceback (most recent call last):
  File "C:\Users\simplon\anaconda3\lib\site-packages\wandb\sdk\lib\retry.py", line 113, in __call__
    result = self._call_fn(*args, **kwargs)
  File "C:\Users\simplon\anaconda3\lib\site-packages\wandb\sdk\internal\internal_api.py", line 209, in execute
    return self.client.execute(*args, **kwargs)  # type: ignore
  File "C:\Users\simplon\anaconda3\lib\site-packages\wandb\vendor\gql-0.2.0\wandb_gql\client.py", line 52, in execute
    result = self._get_result(document, *args, **kwargs)
  File "C:\Users\simplon\anaconda3\lib\site-packages\wandb\vendor\gql-0.2.0\wandb_gql\client.py", line 60, in _get_result
    return self.transport.execute(document, *args, **kwargs)
  File "C:\Users\simplon\anaconda3\lib\site-packages\wandb\vendor\gql-0.2.0\wandb_gql\transport\requests.py", line 38, in execute
    request = requests.post(self.url, **post_args)
  File "C:\Users\simplon\anaconda3\lib\site-packages\requests\api.py", line 115, in post
    return request("post", url, data=data, json=json, **kwargs)
  File "C:\Users\simplon\anaconda3\lib\site-packages\requests\api.py", line 59, in request
    return session.request(method=method, url=url, **kwargs)
  File "C:\Users\simplon\anaconda3\lib\site-packages\requests\sessions.py", line 587, in request
    resp = self.send(prep, **send_kwargs)
  File "C:\Users\simplon\anaconda3\lib\site-packages\requests\sessions.py", line 701, in send
    r = adapter.send(request, **kwargs)
  File "C:\Users\simplon\anaconda3\lib\site-packages\requests\adapters.py", line 565, in send
    raise ConnectionError(e, request=request)
requests.exceptions.ConnectionError: HTTPSConnectionPool(host='api.wandb.ai', port=443): Max retries exceeded with url: /graphql (Caused by NewConnectionError('<urllib3.connection.HTTPSConnection object at 0x0000020E88446820>: Failed to establish a new connection: [Errno 11001] getaddrinfo failed'))
2023-01-02 11:07:00,543 DEBUG   HandlerThread:9560 [handler.py:handle_request():139] handle_request: keepalive
2023-01-02 11:07:05,568 DEBUG   HandlerThread:9560 [handler.py:handle_request():139] handle_request: keepalive
2023-01-02 11:07:10,604 DEBUG   HandlerThread:9560 [handler.py:handle_request():139] handle_request: keepalive
2023-01-02 11:07:15,643 DEBUG   HandlerThread:9560 [handler.py:handle_request():139] handle_request: keepalive
2023-01-02 11:07:20,678 DEBUG   HandlerThread:9560 [handler.py:handle_request():139] handle_request: keepalive
2023-01-02 11:07:25,718 DEBUG   HandlerThread:9560 [handler.py:handle_request():139] handle_request: keepalive
2023-01-02 11:07:30,743 DEBUG   HandlerThread:9560 [handler.py:handle_request():139] handle_request: keepalive
2023-01-02 11:07:35,766 DEBUG   HandlerThread:9560 [handler.py:handle_request():139] handle_request: keepalive
2023-01-02 11:07:40,800 DEBUG   HandlerThread:9560 [handler.py:handle_request():139] handle_request: keepalive
2023-01-02 11:07:45,832 DEBUG   HandlerThread:9560 [handler.py:handle_request():139] handle_request: keepalive
2023-01-02 11:07:50,874 DEBUG   HandlerThread:9560 [handler.py:handle_request():139] handle_request: keepalive
2023-01-02 12:54:37,505 INFO    SenderThread:9560 [dir_watcher.py:__init__():216] watching files in: C:\Users\simplon\Desktop\Notebooks\Dossier_Projet_Fil_Rouge\Notebook\wandb\run-20230102_110654-24m9el1p\files
2023-01-02 12:54:37,505 INFO    SenderThread:9560 [sender.py:_start_run_threads():928] run started: 24m9el1p with start time 1672654015.025755
